Workbook

Sheet Feuil1
A2: Production nette
A4: AUTO
B6: SOFAC | C6: WFSLF | D6: RCI | E6: VIVALIS | F6: EQDOM | G6: SALAFIN | J6: Marché
A8: ='Syn prin concurents'!$F$13 -> 45722 | B8: ='Syn prin concurents'!F16 -> 2374846.4 | C8: ='Syn prin concurents'!$F$18 -> 1394520.5 | D8: ='Syn prin concurents'!$F$24 -> 776137.95 | E8: ='Syn prin concurents'!$F$20 -> 1034282.2 | F8: ='Syn prin concurents'!F22 -> 543784.17 | G8: ='Syn prin concurents'!F26 -> 142561.56 | I8: ='Syn prin concurents'!$F$13 -> 45722 | J8: ='Syn prin concurents'!F30 -> 6438156.4
A9: ='Syn prin concurents'!$B$2 -> 46082 | B9: ='Syn prin concurents'!E16 -> 2870929.1 | C9: ='Syn prin concurents'!$E$18 -> 1410372.7 | D9: ='Syn prin concurents'!$E$24 -> 878735.06 | E9: ='Syn prin concurents'!$E$20 -> 781065.78 | F9: ='Syn prin concurents'!E22 -> 655331.21 | G9: ='Syn prin concurents'!E26 -> 151024.44 | I9: ='Syn prin concurents'!$B$2 -> 46082 | J9: ='Syn prin concurents'!E30 -> 6958882.1
A12: Part de Marché
B14: SOFAC | C14: WAFASALAF | D14: VIVALIS | E14: RCI | F14: EQDOM | G14: SALAFIN | H14: AXA
A16: ='Syn prin concurents'!$F$13 -> 45722 | B16: ='Syn prin concurents'!F17 -> 0.36887057 | C16: ='Syn prin concurents'!F19 -> 0.21660246 | D16: ='Syn prin concurents'!F21 -> 0.16064882 | E16: ='Syn prin concurents'!F25 -> 0.12055283 | F16: ='Syn prin concurents'!F23 -> 0.084462715 | G16: ='Syn prin concurents'!F27 -> 0.022143227 | H16: ='Syn prin concurents'!F29 -> 0.00046931276
A17: ='Syn prin concurents'!$B$2 -> 46082 | B17: ='Syn prin concurents'!E17 -> 0.41255608 | C17: ='Syn prin concurents'!E19 -> 0.2026723 | D17: ='Syn prin concurents'!E21 -> 0.11224012 | E17: ='Syn prin concurents'!E25 -> 0.12627532 | F17: ='Syn prin concurents'!E23 -> 0.094171908 | G17: ='Syn prin concurents'!E27 -> 0.021702399 | H17: ='Syn prin concurents'!E29 -> 0.0001344032
A19: ='Syn prin concurents'!$B$2 -> 46082
F20: ='Syn prin concurents'!$F$13 -> 45722 | G20: ='Syn prin concurents'!$E$13 -> 46082
A21: WFSLF | B21: =+'Syn prin concurents'!E19 -> 0.2026723 | D21: SOFAC | F21: =+'Syn prin concurents'!F17 -> 0.36887057 | G21: =+'Syn prin concurents'!E17 -> 0.41255608
A22: VIVALIS | B22: =+'Syn prin concurents'!E17 -> 0.41255608 | D22: WFSLF | F22: =+'Syn prin concurents'!$F$19 -> 0.21660246 | G22: =+'Syn prin concurents'!$E$19 -> 0.2026723
A23: SOFAC | B23: =+'Syn prin concurents'!E21 -> 0.11224012 | D23: RCI | F23: =+'Syn prin concurents'!$F$25 -> 0.12055283 | G23: =+'Syn prin concurents'!$E$25 -> 0.12627532
A24: RCI | B24: =+'Syn prin concurents'!E25 -> 0.12627532 | D24: VIVALIS | F24: =+'Syn prin concurents'!$F$21 -> 0.16064882 | G24: =+'Syn prin concurents'!$E$21 -> 0.11224012
A25: EQDOM | B25: =+'Syn prin concurents'!E23 -> 0.094171908 | D25: EQDOM | F25: =+'Syn prin concurents'!F23 -> 0.084462715 | G25: =+'Syn prin concurents'!E23 -> 0.094171908
A26: SALAFIN | B26: =+'Syn prin concurents'!E27 -> 0.021702399 | D26: SALAFIN | F26: =+'Syn prin concurents'!F27 -> 0.022143227 | G26: =+'Syn prin concurents'!E27 -> 0.021702399
A27: Autres | B27: =+('Syn prin concurents'!E30-'Syn prin concurents'!E18-'Syn prin concurents'!E16-'Syn prin concurents'!E20-'Syn prin concurents'!E24-'Syn prin concurents'!E22-'Syn prin concurents'!E26)/'Syn prin concurents'!E30 -> 0.030381872 | D27: Autres | F27: =+('Syn prin concurents'!F30-'Syn prin concurents'!F18-'Syn prin concurents'!F16-'Syn prin concurents'!F20-'Syn prin concurents'!F24-'Syn prin concurents'!F22-'Syn prin concurents'!F26)/'Syn prin concurents'!F30 -> 0.026719393 | G27: =+('Syn prin concurents'!E30-'Syn prin concurents'!E18-'Syn prin concurents'!E16-'Syn prin concurents'!E20-'Syn prin concurents'!E24-'Syn prin concurents'!E22-'Syn prin concurents'!E26)/'Syn prin concurents'!E30 -> 0.030381872
A29: ='Syn prin concurents'!$F$13 -> 45722
A31: WFSLF | B31: =+'Syn prin concurents'!F19 -> 0.21660246
A32: VIVALIS | B32: =+'Syn prin concurents'!F17 -> 0.36887057
A33: SOFAC | B33: =+'Syn prin concurents'!F21 -> 0.16064882
A34: RCI | B34: =+'Syn prin concurents'!F25 -> 0.12055283
A35: EQDOM | B35: =+'Syn prin concurents'!F23 -> 0.084462715
A36: SALAFIN | B36: =+'Syn prin concurents'!F27 -> 0.022143227
A37: Autres | B37: =+('Syn prin concurents'!F30-'Syn prin concurents'!F18-'Syn prin concurents'!F16-'Syn prin concurents'!F20-'Syn prin concurents'!F24-'Syn prin concurents'!F22-'Syn prin concurents'!F26)/'Syn prin concurents'!F30 -> 0.026719393
A40: Production nette
A42: PP
B44: WFSLF | C44: SOFAC | D44: EQDOM | E44: VIVALIS | F44: SALAFIN | G44: RCI | J44: Marché
A46: ='Syn prin concurents'!$F$13 -> 45722 | B46: =+'Syn prin concurents'!$J18 -> 716594.4 | C46: =+'Syn prin concurents'!$J16 -> 365996.14 | D46: =+'Syn prin concurents'!$J22 -> 375445.19 | E46: =+'Syn prin concurents'!$J$20 -> 324761.03 | F46: =+'Syn prin concurents'!$J$26 -> 126212.98 | G46: =+'Syn prin concurents'!$J24 -> 0 | I46: ='Syn prin concurents'!$F$13 -> 45722 | J46: =+'Syn prin concurents'!$J30 -> 2071586
A47: ='Syn prin concurents'!$B$2 -> 46082 | B47: =+'Syn prin concurents'!$I18 -> 662385.77 | C47: =+'Syn prin concurents'!$I16 -> 427944.8 | D47: =+'Syn prin concurents'!$I22 -> 284808.22 | E47: =+'Syn prin concurents'!$I$20 -> 212657.49 | F47: =+'Syn prin concurents'!$I$26 -> 100851.57 | G47: =+'Syn prin concurents'!$I24 -> 0 | I47: ='Syn prin concurents'!$B$2 -> 46082 | J47: =+'Syn prin concurents'!$I30 -> 1790010.5
A50: ='Syn prin concurents'!$B$2 -> 46082
F51: ='Syn prin concurents'!$F$13 -> 45722 | G51: ='Syn prin concurents'!$E$13 -> 46082
A52: WFSLF | B52: =+'Syn prin concurents'!I19 -> 0.37004575 | D52: WFSLF | F52: =+'Syn prin concurents'!J19 -> 0.34591583 | G52: =+'Syn prin concurents'!I19 -> 0.37004575
A53: EQDOM | B53: =+'Syn prin concurents'!I17 -> 0.23907391 | D53: SOFAC | F53: =+'Syn prin concurents'!J17 -> 0.17667436 | G53: =+'Syn prin concurents'!I17 -> 0.23907391
A54: SOFAC | B54: =+'Syn prin concurents'!I21 -> 0.11880237 | D54: EQDOM | F54: =+'Syn prin concurents'!J23 -> 0.18123563 | G54: =+'Syn prin concurents'!I23 -> 0.1591098
A55: VIVALIS | B55: =+'Syn prin concurents'!I25 -> 0 | D55: VIVALIS | F55: =+'Syn prin concurents'!$J$21 -> 0.15676927 | G55: =+'Syn prin concurents'!$I$21 -> 0.11880237
A56: SALAFIN | B56: =+'Syn prin concurents'!I23 -> 0.1591098 | D56: SALAFIN | F56: =+'Syn prin concurents'!$J$27 -> 0.060925772 | G56: =+'Syn prin concurents'!$I$27 -> 0.056341329
A57: Autres | B57: =+('Syn prin concurents'!I30-'Syn prin concurents'!I18-'Syn prin concurents'!I16-'Syn prin concurents'!I20-'Syn prin concurents'!I24-'Syn prin concurents'!I22-'Syn prin concurents'!I26)/'Syn prin concurents'!I30 -> 0.056626841 | D57: Autres | F57: =+('Syn prin concurents'!J30-'Syn prin concurents'!J18-'Syn prin concurents'!J16-'Syn prin concurents'!J20-'Syn prin concurents'!J24-'Syn prin concurents'!J22-'Syn prin concurents'!J26)/'Syn prin concurents'!J30 -> 0.078479135 | G57: =+('Syn prin concurents'!I30-'Syn prin concurents'!I18-'Syn prin concurents'!I16-'Syn prin concurents'!I20-'Syn prin concurents'!I24-'Syn prin concurents'!I22-'Syn prin concurents'!I26)/'Syn prin concurents'!I30 -> 0.056626841
A59: ='Syn prin concurents'!$F$13 -> 45722
...

Sheet Feuil2
B2: WFSLF 2016 | C2: WFSLF 2017 | E2: EQDOM 2016 | F2: EQDOM 2017 | H2: SOFAC 2016 | I2: SOFAC 2017 | K2: VIVALIS 2016 | L2: VIVALIS 2017 | N2: SALAFIN 2016 | O2: SALAFIN 2017 | Q2: RCI 2016 | R2: RCI 2017 | T2: Marché 2016 | U2: Marché 2017
A4: CA | B4: ='Syn prin concurents par cat (2)'!D16 -> 467803.11 | C4: ='Syn prin concurents par cat (2)'!C16 -> 459172.33 | E4: ='Syn prin concurents par cat (2)'!D18 -> 1209540.1 | F4: ='Syn prin concurents par cat (2)'!C18 -> 1477587.7 | H4: ='Syn prin concurents par cat (2)'!D20 -> 544967.06 | I4: ='Syn prin concurents par cat (2)'!C20 -> 346945.91 | K4: ='Syn prin concurents par cat (2)'!D24 -> 524957.67 | L4: ='Syn prin concurents par cat (2)'!C24 -> 669033.28 | N4: ='Syn prin concurents par cat (2)'!D22 -> 168230.65 | O4: ='Syn prin concurents par cat (2)'!C22 -> 234377.66 | Q4: ='Syn prin concurents par cat (2)'!D26 -> 57604.136 | R4: ='Syn prin concurents par cat (2)'!C26 -> 52268.239 | T4: ='Syn prin concurents par cat (2)'!D30 -> 3143356.6 | U4: ='Syn prin concurents par cat (2)'!C30 -> 3450116.2
A5: LOA | B5: ='Syn prin concurents par cat (2)'!H16 -> 926717.4 | C5: ='Syn prin concurents par cat (2)'!G16 -> 951200.32 | E5: ='Syn prin concurents par cat (2)'!H18 -> 1165306.4 | F5: ='Syn prin concurents par cat (2)'!G18 -> 1393341.4 | H5: ='Syn prin concurents par cat (2)'!H20 -> 489315.15 | I5: ='Syn prin concurents par cat (2)'!G20 -> 434119.87 | K5: ='Syn prin concurents par cat (2)'!H24 -> 251180.28 | L5: ='Syn prin concurents par cat (2)'!G24 -> 209701.78 | N5: ='Syn prin concurents par cat (2)'!H22 -> 375553.52 | O5: ='Syn prin concurents par cat (2)'!G22 -> 420953.54 | Q5: ='Syn prin concurents par cat (2)'!H26 -> 84957.422 | R5: ='Syn prin concurents par cat (2)'!G26 -> 98756.197 | T5: ='Syn prin concurents par cat (2)'!H30 -> 3294311.7 | U5: ='Syn prin concurents par cat (2)'!G30 -> 3508766
A12: Encours Sains marché
B15: 43465 | C15: Banques | D15: SCC | E15: 43555
B17: ='Syn prin concurents'!V54+54077000 -> 1.341146e+08 | C17: 727000 | D17: ='Syn prin concurents'!U54-'Syn prin concurents'!V54 -> 3133845 | E17: e
A21: Production marché
B24: 43190 | C24: PP | D24: AUTO | E24: EDM / Revolvig | F24: 43555
B26: ='Syn prin concurents'!V30 -> 8681416.5 | C26: ='Syn prin concurents'!I30-'Syn prin concurents'!J30 -> -281575.51 | D26: ='Syn prin concurents'!E30-'Syn prin concurents'!F30 -> 520725.68 | E26: ='Syn prin concurents'!M30-'Syn prin concurents'!N30+('Syn prin concurents'!Q30-'Syn prin concurents'!R30) -> 94957.706 | F26: e

Sheet Feuil3
A1: Global | M1: Encours sain
B4: WFSLF | C4: SOFAC | D4: VIVALIS | E4: EQDOM | F4: RCI | G4: SALAFIN | J4: Marché | N4: Fin 03 2022 | O4: Fin 06 2022 | P4: Fin 09 2022 | Q4: Fin 12 2022 | S4: Fin Mars 2022 | T4: Fin Juin 2022 | U4: Fin Septembre 2022 | X4: Fin Mars 2022 | Y4: Fin Juin 2022 | Z4: Fin Septembre 2022
A6: ='Syn prin concurents par trim'!E13 -> T1 | B6: ='Syn prin concurents par trim'!$Y$16 -> 1634995.4 | C6: ='Syn prin concurents par trim'!$Y$18 -> 1704033.9 | D6: ='Syn prin concurents par trim'!$Y$20 -> 1046761.6 | E6: ='Syn prin concurents par trim'!$Y$22 -> 705744.72 | F6: ='Syn prin concurents par trim'!$Y$24 -> 593032.69 | G6: ='Syn prin concurents par trim'!$Y$26 -> 246169.62 | I6: =A6 -> T1 | J6: ='Syn prin concurents par trim'!$Y$30 -> 6241732.4 | M6: WFSLF | N6: =#REF! -> #REF! | O6: ='Syn prin concurents'!$U$42 -> 19525425 | P6: ='Syn prin concurents'!U40 -> 25157206 | W6: Marché | X6: ='[1]Syn prin concurents'!$U$54 -> 62726433 | Y6: ='Syn prin concurents'!$U$54 -> 83171449 | Z6: ='Syn prin concurents'!U54 -> 83171449
A7: ='Syn prin concurents par trim'!F13 -> T2 | B7: ='Syn prin concurents par trim'!$Z$16 -> 1945128.2 | C7: ='Syn prin concurents par trim'!$Z$18 -> 1571495.5 | D7: ='Syn prin concurents par trim'!$Z$20 -> 1582837.7 | E7: ='Syn prin concurents par trim'!$Z$22 -> 747398.62 | F7: ='Syn prin concurents par trim'!$Z$24 -> 675311.69 | G7: ='Syn prin concurents par trim'!$Z$26 -> 268512.79 | I7: =A7 -> T2 | J7: ='Syn prin concurents par trim'!$Z$30 -> 7057059 | M7: RCI | N7: ='[1]Syn prin concurents'!$U$46 -> 8199878.4 | O7: ='Syn prin concurents'!$U$46 -> 9993113.1 | P7: ='Syn prin concurents'!U48 -> 6280424.6
A8: T3 | B8: ='Syn prin concurents par trim'!$AA$16 -> 1880202 | C8: ='Syn prin concurents par trim'!$AA$18 -> 1502086.2 | D8: ='Syn prin concurents par trim'!$AA$20 -> 1182918.6 | E8: ='Syn prin concurents par trim'!$AA$22 -> 708407.58 | F8: ='Syn prin concurents par trim'!$AA$24 -> 566978.85 | G8: ='Syn prin concurents par trim'!$AA$26 -> 221282.97 | I8: T3 | J8: ='Syn prin concurents par trim'!$AA$30 -> 6331990.9 | M8: EQDOM | N8: ='[1]Syn prin concurents'!$U$48 -> 4441192.5 | O8: ='Syn prin concurents'!$U$48 -> 6280424.6 | P8: ='Syn prin concurents'!U46 -> 9993113.1 | S8: Fin Mars 2022 | T8: Fin Juin 2022 | U8: Fin Septembre 2022
A9: T4 | B9: ='Syn prin concurents par trim'!$AB$16 -> -3123492.8 | C9: ='Syn prin concurents par trim'!$AB$18 -> -1477598.6 | D9: ='Syn prin concurents par trim'!$AB$20 -> -2818794.6 | E9: ='Syn prin concurents par trim'!$AB$22 -> -1221240.2 | F9: ='Syn prin concurents par trim'!$AB$24 -> -956588.16 | G9: ='Syn prin concurents par trim'!$AB$26 -> -482846.36 | I9: T4 | J9: ='Syn prin concurents par trim'!$AB$30 -> -10615258 | M9: SALAFIN | N9: ='[1]Syn prin concurents'!$U$50 -> 2667926 | O9: ='Syn prin concurents'!$U$50 -> 2505963.4 | P9: ='Syn prin concurents'!U50 -> 2505963.4
M10: SOFAC | N10: ='[1]Syn prin concurents'!$U$42 -> 13503209 | O10: ='Syn prin concurents'!$U$40 -> 25157206 | P10: ='Syn prin concurents'!U42 -> 19525425
M11: VIVALIS | N11: ='[1]Syn prin concurents'!$U$44 -> 13568646 | O11: ='Syn prin concurents'!$U$44 -> 16332672 | P11: ='Syn prin concurents'!U44 -> 16332672
C12: T1 | D12: T2 | E12: T3 | F12: T4 | S12: Fin Mars 2022 | T12: Fin Juin 2022 | U12: Fin Septembre 2022
A13: WFSLF | C13: ='Syn prin concurents par trim'!$Y$17 -> 0.26194577 | D13: ='Syn prin concurents par trim'!$Z$17 -> 0.27562873 | E13: ='Syn prin concurents par trim'!$AA$17 -> 0.29693694 | F13: ='Syn prin concurents par trim'!$AB$17 -> 0.29424559 | N13: Fin 03 2022 | O13: Fin 06 2022 | P13: Fin 09 2022
A14: SOFAC | C14: ='Syn prin concurents par trim'!$Y$19 -> 0.27300657 | D14: ='Syn prin concurents par trim'!$Z$19 -> 0.22268419 | E14: ='Syn prin concurents par trim'!$AA$19 -> 0.23722179 | F14: ='Syn prin concurents par trim'!$AB$19 -> 0.13919574
A15: VIVALIS | C15: ='Syn prin concurents par trim'!$Y$21 -> 0.1677037 | D15: ='Syn prin concurents par trim'!$Z$21 -> 0.2242914 | E15: ='Syn prin concurents par trim'!$AA$21 -> 0.18681622 | F15: ='Syn prin concurents par trim'!$AB$21 -> 0.26554179 | M15: Marché | N15: 53521667 | O15: 55862869 | P15: 55874222
A16: EQDOM | C16: ='Syn prin concurents par trim'!$Y$23 -> 0.11306872 | D16: ='Syn prin concurents par trim'!$Z$23 -> 0.10590795 | E16: ='Syn prin concurents par trim'!$AA$23 -> 0.11187754 | F16: ='Syn prin concurents par trim'!$AB$23 -> 0.11504574
A17: RCI | C17: ='Syn prin concurents par trim'!$Y$25 -> 0.095010911 | D17: ='Syn prin concurents par trim'!$Z$25 -> 0.095693077 | E17: ='Syn prin concurents par trim'!$AA$25 -> 0.089541955 | F17: ='Syn prin concurents par trim'!$AB$25 -> 0.090114453 | M17: CES/EB
A18: SALAFIN | C18: ='Syn prin concurents par trim'!$Y$27 -> 0.03943931 | D18: ='Syn prin concurents par trim'!$Z$27 -> 0.038048823 | E18: ='Syn prin concurents par trim'!$AA$27 -> 0.034946824 | F18: ='Syn prin concurents par trim'!$AB$27 -> 0.045486069
A19: Autres | C19: =('Syn prin concurents par trim'!$Y$30-'Syn prin concurents par trim'!$Y$18-'Syn prin concurents par trim'!$Y$16-'Syn prin concurents par trim'!$Y$24-'Syn prin concurents par trim'!$Y$20-'Syn prin concurents par trim'!$Y$22-'Syn prin concurents par trim'!$Y$26-'Syn prin concurents par trim'!$Y$28)/'Syn prin concurents par trim'!$Y$30 -> 0.026563788 | D19: =('Syn prin concurents par trim'!$Z$30-'Syn prin concurents par trim'!$Z$18-'Syn prin concurents par trim'!$Z$16-'Syn prin concurents par trim'!$Z$24-'Syn prin concurents par trim'!$Z$20-'Syn prin concurents par trim'!$Z$22-'Syn prin concurents par trim'!$Z$26-'Syn prin concurents par trim'!$Z$28)/'Syn prin concurents par trim'!$Z$30 -> 0.019183248 | E19: =('Syn prin concurents par trim'!$AA$30-'Syn prin concurents par trim'!$AA$18-'Syn prin concurents par trim'!$AA$16-'Syn prin concurents par trim'!$AA$24-'Syn prin concurents par trim'!$AA$20-'Syn prin concurents par trim'!$AA$22-'Syn prin concurents par trim'!$AA$26-'Syn prin concurents par trim'!$AA$28)/'Syn prin concurents par trim'!$AA$30 -> 0.019540254 | F19: =('Syn prin concurents par trim'!$AB$30-'Syn prin concurents par trim'!$AB$18-'Syn prin concurents par trim'!$AB$16-'Syn prin concurents par trim'!$AB$24-'Syn prin concurents par trim'!$AB$20-'Syn prin concurents par trim'!$AB$22-'Syn prin concurents par trim'!$AB$26-'Syn prin concurents par trim'!$AB$28)/'Syn prin concurents par trim'!$AB$30 -> 0.019440632
N20: Fin 03 2022 | O20: Fin 06 2022 | P20: Fin 09 2022
A22: AUTO | M22: WFSLF | N22: =+'[1]Syn prin concurents'!$U$110 -> 0.22893224 | O22: =+'Syn prin concurents'!$U$115 -> 0.11040646 | P22: =+'Syn prin concurents'!#REF! -> #REF!
M23: SOFAC | N23: =+'[1]Syn prin concurents'!$U$111 -> 0.18823776 | O23: =+'Syn prin concurents'!#REF! -> #REF! | P23: =+'Syn prin concurents'!U115 -> 0.11040646
B24: SOFAC | C24: VIVALIS | D24: WFSLF | E24: RCI | F24: EQDOM | G24: SALAFIN | J24: Marché | M24: VIVALIS | N24: =+'[1]Syn prin concurents'!$U$112 -> 0.18765181 | O24: =+'Syn prin concurents'!$U$116 -> 0.16140025 | P24: =+'Syn prin concurents'!U116 -> 0.16140025
M25: EQDOM | N25: =+'[1]Syn prin concurents'!$U$114 -> 0.12345176 | O25: =+'Syn prin concurents'!$U$113 -> 0.12052688 | P25: =+'Syn prin concurents'!U111 -> 0.15198609
A26: T1 | B26: ='Syn prin concurents par trim'!$E$18 -> 1394379.6 | C26: ='Syn prin concurents par trim'!$E$20 -> 768372.06 | D26: ='Syn prin concurents par trim'!$E$16 -> 826975.06 | E26: ='Syn prin concurents par trim'!$E$24 -> 593032.69 | F26: ='Syn prin concurents par trim'!$E$22 -> 368706.86 | G26: ='Syn prin concurents par trim'!$E$26 -> 121150.02 | I26: T1 | J26: ='Syn prin concurents par trim'!$E$30 -> 4217809.5 | M26: RCI | N26: =+'[1]Syn prin concurents'!$U$113 -> 0.13799758 | O26: =+'Syn prin concurents'!$U$111 -> 0.15198609 | P26: =+'Syn prin concurents'!U113 -> 0.12052688
A27: T2 | B27: ='Syn prin concurents par trim'!$F$18 -> 1288206.4 | C27: ='Syn prin concurents par trim'!$F$20 -> 1264426.2 | D27: ='Syn prin concurents par trim'!$F$16 -> 1014273.7 | E27: ='Syn prin concurents par trim'!$F$24 -> 675311.69 | F27: ='Syn prin concurents par trim'!$F$22 -> 374165.16 | G27: ='Syn prin concurents par trim'!$F$26 -> 144083.33 | I27: T2 | J27: ='Syn prin concurents par trim'!$F$30 -> 4897586.8 | M27: SALAFIN | N27: =+'[1]Syn prin concurents'!$U$115 -> 0.10482851 | O27: =+'Syn prin concurents'!$U$110 -> 0.2769831 | P27: =+'Syn prin concurents'!U110 -> 0.2769831
A28: T3 | B28: ='Syn prin concurents par trim'!$G$18 -> 1208298.1 | C28: ='Syn prin concurents par trim'!$G$20 -> 843832.47 | D28: ='Syn prin concurents par trim'!$G$16 -> 997576.37 | E28: ='Syn prin concurents par trim'!$G$24 -> 566978.85 | F28: ='Syn prin concurents par trim'!$G$22 -> 319322.78 | G28: ='Syn prin concurents par trim'!$G$26 -> 111793.54 | I28: T3 | J28: ='Syn prin concurents par trim'!$G$30 -> 4170695.1 | M28: Marché | N28: =+'[1]Syn prin concurents'!$U$117 -> 0.13351451 | O28: =+'Syn prin concurents'!$U$117 -> 0.13185744 | P28: =+'Syn prin concurents'!U117 -> 0.13185744
A29: T4 | B29: ='Syn prin concurents par trim'!$H$18 -> -1019955 | C29: ='Syn prin concurents par trim'!$H$20 -> -2095564.9 | D29: ='Syn prin concurents par trim'!$H$16 -> -1428452.5 | E29: ='Syn prin concurents par trim'!$H$24 -> -956588.16 | F29: ='Syn prin concurents par trim'!$H$22 -> -406863.59 | G29: ='Syn prin concurents par trim'!$H$26 -> -226002.45 | I29: T4 | J29: ='Syn prin concurents par trim'!$H$30 -> -6327209.3
C32: T1 | D32: T2 | E32: T3 | F32: T4
A33: SOFAC | C33: ='Syn prin concurents par trim'!$E$19 -> 0.33059331 | D33: ='Syn prin concurents par trim'!$F$19 -> 0.2630288 | E33: ='Syn prin concurents par trim'!$G$19 -> 0.28971144 | F33: ='Syn prin concurents par trim'!$H$19 -> 0.16120139
A34: VIVALIS | C34: ='Syn prin concurents par trim'!$E$21 -> 0.18217325 | D34: ='Syn prin concurents par trim'!$F$21 -> 0.2581733 | E34: ='Syn prin concurents par trim'!$G$21 -> 0.20232418 | F34: ='Syn prin concurents par trim'!$H$21 -> 0.33119892
A35: WFSLF | C35: ='Syn prin concurents par trim'!$E$17 -> 0.19606743 | D35: ='Syn prin concurents par trim'!$F$17 -> 0.20709663 | E35: ='Syn prin concurents par trim'!$G$17 -> 0.23918708 | F35: ='Syn prin concurents par trim'!$H$17 -> 0.22576343
A36: RCI | C36: ='Syn prin concurents par trim'!$E$25 -> 0.14060205 | D36: ='Syn prin concurents par trim'!$F$25 -> 0.13788662 | E36: ='Syn prin concurents par trim'!$G$25 -> 0.13594349 | F36: ='Syn prin concurents par trim'!$H$25 -> 0.15118643
A37: EQDOM | C37: ='Syn prin concurents par trim'!$E$23 -> 0.087416668 | D37: ='Syn prin concurents par trim'!$F$23 -> 0.076397861 | E37: ='Syn prin concurents par trim'!$G$23 -> 0.076563443 | F37: ='Syn prin concurents par trim'!$H$23 -> 0.064303797
A38: SALAFIN | C38: ='Syn prin concurents par trim'!$E$27 -> 0.028723446 | D38: ='Syn prin concurents par trim'!$F$27 -> 0.029419249 | E38: ='Syn prin concurents par trim'!$G$27 -> 0.026804534 | F38: ='Syn prin concurents par trim'!$H$27 -> 0.035719137
A39: Autres | C39: =('Syn prin concurents par trim'!$E$30-'Syn prin concurents par trim'!$E$18-'Syn prin concurents par trim'!$E$16-'Syn prin concurents par trim'!$E$24-'Syn prin concurents par trim'!E20-'Syn prin concurents par trim'!$E$22-'Syn prin concurents par trim'!$E$26-'Syn prin concurents par trim'!$E$28)/'Syn prin concurents par trim'!$E$30 -> 0.033672825 | D39: =('Syn prin concurents par trim'!$F$30-'Syn prin concurents par trim'!$F$18-'Syn prin concurents par trim'!$F$16-'Syn prin concurents par trim'!$F$24-'Syn prin concurents par trim'!F20-'Syn prin concurents par trim'!$F$22-'Syn prin concurents par trim'!$F$26-'Syn prin concurents par trim'!$F$28)/'Syn prin concurents par trim'!$F$30 -> 0.027320859 | E39: =('Syn prin concurents par trim'!$G$30-'Syn prin concurents par trim'!$G$18-'Syn prin concurents par trim'!$G$16-'Syn prin concurents par trim'!$G$24-'Syn prin concurents par trim'!G20-'Syn prin concurents par trim'!$G$22-'Syn prin concurents par trim'!$G$26-'Syn prin concurents par trim'!$G$28)/'Syn prin concurents par trim'!$G$30 -> 0.029246496 | F39: =('Syn prin concurents par trim'!$H$30-'Syn prin concurents par trim'!$H$18-'Syn prin concurents par trim'!$H$16-'Syn prin concurents par trim'!$H$24-'Syn prin concurents par trim'!H20-'Syn prin concurents par trim'!$H$22-'Syn prin concurents par trim'!$H$26-'Syn prin concurents par trim'!$H$28)/'Syn prin concurents par trim'!$H$30 -> 0.029605704
A42: PP
B44: WFSLF | C44: EQDOM | D44: SOFAC | E44: VIVALIS | F44: SALAFIN | J44: Marché
A46: T1 | B46: ='Syn prin concurents par trim'!$J$16 -> 638934.88 | C46: ='Syn prin concurents par trim'!$J$22 -> 336925.96 | D46: ='Syn prin concurents par trim'!$J$18 -> 307507.01 | E46: ='Syn prin concurents par trim'!$J$20 -> 278389.54 | F46: ='Syn prin concurents par trim'!$J$26 -> 119043.47 | I46: T1 | J46: ='Syn prin concurents par trim'!$J$30 -> 1846602.1
A47: T2 | B47: ='Syn prin concurents par trim'!$K$16 -> 775244.45 | C47: ='Syn prin concurents par trim'!$K$22 -> 373055.24 | D47: ='Syn prin concurents par trim'!$K$18 -> 282195.05 | E47: ='Syn prin concurents par trim'!$K$20 -> 318411.51 | F47: ='Syn prin concurents par trim'!$K$26 -> 129162.57 | I47: T2 | J47: ='Syn prin concurents par trim'!$K$30 -> 2006518
A48: T3 | B48: ='Syn prin concurents par trim'!$L$16 -> 740352.67 | C48: ='Syn prin concurents par trim'!$L$22 -> 388462.17 | D48: ='Syn prin concurents par trim'!$L$18 -> 293267.67 | E48: ='Syn prin concurents par trim'!$L$20 -> 339086.12 | F48: ='Syn prin concurents par trim'!$L$26 -> 111958.99 | I48: T3 | J48: ='Syn prin concurents par trim'!$L$30 -> 2020349.3
A49: T4 | B49: ='Syn prin concurents par trim'!$M$16 -> -1492146.2 | C49: ='Syn prin concurents par trim'!$M$22 -> -813635.15 | D49: ='Syn prin concurents par trim'!$M$18 -> -455024.92 | E49: ='Syn prin concurents par trim'!$M$20 -> -723229.68 | F49: ='Syn prin concurents par trim'!$M$26 -> -259313.46 | I49: T4 | J49: ='Syn prin concurents par trim'!$M$30 -> -4083458.9
C52: T1 | D52: T2 | E52: T3 | F52: T4
...

Sheet Feuil4
A1: Global
B4: WFSLF | C4: SOFAC | D4: EQDOM | E4: VIVALIS | F4: RCI | G4: SALAFIN | J4: Marché
A6: 2019 | B6: ='Syn prin concurents par sem'!$Q$16 -> 3017981.9 | C6: ='Syn prin concurents par sem'!$Q$18 -> 2450472.2 | D6: ='Syn prin concurents par sem'!$Q$20 -> 1130208 | E6: ='Syn prin concurents par sem'!$Q$22 -> 2273893.3 | F6: ='Syn prin concurents par sem'!$Q$24 -> 879518.89 | G6: ='Syn prin concurents par sem'!$Q$26 -> 474031.78 | I6: 2019 | J6: ='Syn prin concurents par sem'!$Q$30 -> 10793575
A7: 2020 | B7: ='Syn prin concurents par sem'!$R$16 -> #REF! | C7: ='Syn prin concurents par sem'!$R$18 -> #REF! | D7: ='Syn prin concurents par sem'!$R$20 -> #REF! | E7: ='Syn prin concurents par sem'!$R$22 -> #REF! | F7: ='Syn prin concurents par sem'!$R$24 -> #REF! | G7: ='Syn prin concurents par sem'!$R$26 -> #REF! | I7: 2020 | J7: ='Syn prin concurents par sem'!$R$30 -> #REF!
C10: 2019 | D10: 2020
A11: WFSLF | C11: ='Syn prin concurents par sem'!$Q$17 -> 0.27960911 | D11: ='Syn prin concurents par sem'!$R$17 -> #REF!
A12: SOFAC | C12: ='Syn prin concurents par sem'!$Q$19 -> 0.22703064 | D12: ='Syn prin concurents par sem'!$R$19 -> #REF!
A13: EQDOM | C13: ='Syn prin concurents par sem'!$Q$21 -> 0.10471119 | D13: ='Syn prin concurents par sem'!$R$21 -> #REF!
A14: VIVALIS | C14: ='Syn prin concurents par sem'!$Q$23 -> 0.210671 | D14: ='Syn prin concurents par sem'!$R$23 -> #REF!
A15: RCI | C15: ='Syn prin concurents par sem'!$Q$25 -> 0.081485412 | D15: ='Syn prin concurents par sem'!$R$25 -> #REF!
A16: SALAFIN | C16: ='Syn prin concurents par sem'!$Q$27 -> 0.043917959 | D16: ='Syn prin concurents par sem'!$R$27 -> #REF!
A17: Autres | C17: =('Syn prin concurents par sem'!$Q$30-'Syn prin concurents par sem'!$Q$16-'Syn prin concurents par sem'!$Q$18-'Syn prin concurents par sem'!$Q$20-'Syn prin concurents par sem'!$Q$22-'Syn prin concurents par sem'!$Q$24-'Syn prin concurents par sem'!$Q$26-'Syn prin concurents par sem'!$Q$28)/'Syn prin concurents par sem'!$Q$30 -> 0.02572091 | D17: =('Syn prin concurents par sem'!$R$30-'Syn prin concurents par sem'!$R$16-'Syn prin concurents par sem'!$R$18-'Syn prin concurents par sem'!$R$20-'Syn prin concurents par sem'!$R$22-'Syn prin concurents par sem'!$R$24-'Syn prin concurents par sem'!$R$26-'Syn prin concurents par sem'!$R$28)/'Syn prin concurents par sem'!$R$30 -> #REF!
A20: AUTO
B22: WFSLF | C22: SOFAC | D22: EQDOM | E22: VIVALIS | F22: RCI | G22: SALAFIN | J22: Marché
A24: 2019 | B24: ='Syn prin concurents par sem'!$E$16 -> 1418652.2 | C24: ='Syn prin concurents par sem'!$E$18 -> 1971219.5 | D24: ='Syn prin concurents par sem'!$E$20 -> 512605.36 | E24: ='Syn prin concurents par sem'!$E$22 -> 1679049.8 | F24: ='Syn prin concurents par sem'!$E$24 -> 879518.89 | G24: ='Syn prin concurents par sem'!$E$26 -> 227558.18 | I24: 2019 | J24: ='Syn prin concurents par sem'!$E$30 -> 6938253.8
A25: 2020 | B25: ='Syn prin concurents par sem'!$F$16 -> #REF! | C25: ='Syn prin concurents par sem'!$F$18 -> #REF! | D25: ='Syn prin concurents par sem'!$F$20 -> #REF! | E25: ='Syn prin concurents par sem'!$F$22 -> #REF! | F25: ='Syn prin concurents par sem'!$F$24 -> #REF! | G25: ='Syn prin concurents par sem'!$F$26 -> #REF! | I25: 2020 | J25: ='Syn prin concurents par sem'!$F$30 -> #REF!
C28: 2019 | D28: 2020
A29: WFSLF | C29: ='Syn prin concurents par sem'!$E$17 -> 0.20446819 | D29: ='Syn prin concurents par sem'!$F$17 -> #REF!
A30: SOFAC | C30: ='Syn prin concurents par sem'!$E$19 -> 0.28410888 | D30: ='Syn prin concurents par sem'!$F$19 -> #REF!
A31: EQDOM | C31: ='Syn prin concurents par sem'!$E$21 -> 0.073881034 | D31: ='Syn prin concurents par sem'!$F$21 -> #REF!
A32: VIVALIS | C32: ='Syn prin concurents par sem'!$E$23 -> 0.2419989 | D32: ='Syn prin concurents par sem'!$F$23 -> #REF!
A33: RCI | C33: ='Syn prin concurents par sem'!$E$25 -> 0.12676373 | D33: ='Syn prin concurents par sem'!$F$25 -> #REF!
A34: SALAFIN | C34: ='Syn prin concurents par sem'!$E$27 -> 0.032797615 | D34: ='Syn prin concurents par sem'!$F$27 -> #REF!
A35: Autres | C35: =('Syn prin concurents par sem'!$E$30-'Syn prin concurents par sem'!$E$16-'Syn prin concurents par sem'!$E$18-'Syn prin concurents par sem'!$E$20-'Syn prin concurents par sem'!$E$22-'Syn prin concurents par sem'!$E$24-'Syn prin concurents par sem'!$E$26-'Syn prin concurents par sem'!$E$28)/'Syn prin concurents par sem'!$E$30 -> 0.035618519 | D35: =('Syn prin concurents par sem'!$F$30-'Syn prin concurents par sem'!$F$16-'Syn prin concurents par sem'!$F$18-'Syn prin concurents par sem'!$F$20-'Syn prin concurents par sem'!$F$22-'Syn prin concurents par sem'!$F$24-'Syn prin concurents par sem'!$F$26-'Syn prin concurents par sem'!$F$28)/'Syn prin concurents par sem'!$F$30 -> #REF!
A38: PP
B40: WFSLF | C40: EQDOM | D40: VIVALIS | E40: SOFAC | F40: SALAFIN | J40: Marché
A42: 2019 | B42: ='Syn prin concurents par sem'!$H$16 -> 1325401.4 | C42: ='Syn prin concurents par sem'!$H$20 -> 617498.16 | D42: ='Syn prin concurents par sem'!$H$22 -> 594843.48 | E42: ='Syn prin concurents par sem'!$H$18 -> 477896.66 | F42: ='Syn prin concurents par sem'!$H$26 -> 243390.06 | I42: 2019 | J42: ='Syn prin concurents par sem'!$H$30 -> 3576848.9
A43: 2020 | B43: ='Syn prin concurents par sem'!$I$16 -> #REF! | C43: ='Syn prin concurents par sem'!$I$20 -> #REF! | D43: ='Syn prin concurents par sem'!$I$22 -> #REF! | E43: ='Syn prin concurents par sem'!$I$18 -> #REF! | F43: ='Syn prin concurents par sem'!$I$26 -> #REF! | I43: 2020 | J43: ='Syn prin concurents par sem'!$I$30 -> #REF!
C46: 2019 | D46: 2020
A47: WFSLF | C47: ='Syn prin concurents par sem'!$H$17 -> 0.37055002 | D47: ='Syn prin concurents par sem'!$I$17 -> #REF!
A48: EQDOM | C48: ='Syn prin concurents par sem'!$H$21 -> 0.17263747 | D48: ='Syn prin concurents par sem'!$I$21 -> #REF!
A49: VIVALIS | C49: ='Syn prin concurents par sem'!$H$23 -> 0.16630378 | D49: ='Syn prin concurents par sem'!$I$23 -> #REF!
A50: SOFAC | C50: ='Syn prin concurents par sem'!$H$19 -> 0.13360829 | D50: ='Syn prin concurents par sem'!$I$19 -> #REF!
A51: SALAFIN | C51: ='Syn prin concurents par sem'!$H$27 -> 0.068045943 | D51: ='Syn prin concurents par sem'!$I$27 -> #REF!
A52: Autres | C52: =('Syn prin concurents par sem'!$H$30-'Syn prin concurents par sem'!$H$16-'Syn prin concurents par sem'!$H$18-'Syn prin concurents par sem'!$H$20-'Syn prin concurents par sem'!$H$22-'Syn prin concurents par sem'!$H$24-'Syn prin concurents par sem'!$H$26-'Syn prin concurents par sem'!$H$28)/'Syn prin concurents par sem'!$H$30 -> 0.00852433 | D52: =('Syn prin concurents par sem'!$I$30-'Syn prin concurents par sem'!$I$16-'Syn prin concurents par sem'!$I$18-'Syn prin concurents par sem'!$I$20-'Syn prin concurents par sem'!$I$22-'Syn prin concurents par sem'!$I$24-'Syn prin concurents par sem'!$I$26-'Syn prin concurents par sem'!$I$28)/'Syn prin concurents par sem'!$I$30 -> #REF!

Sheet Syn prin concurents
B2: =E13 -> 46082
B9: Production nette
E11: Vehicules (en MDH) | I11: Prêts personnels (en MDH) | M11: Equipement domestique (en MDH) | Q11: Revolving (en MDH) | U11: Global (en MDH)
E13: ='Syn prin concurents par catégor'!C13 -> 46082 | F13: =E13-360 -> 45722 | G13: Evolution | I13: =E13 -> 46082 | J13: =F13 -> 45722 | K13: Evolution | M13: =I13 -> 46082 | N13: =J13 -> 45722 | O13: Evolution | Q13: =M13 -> 46082 | R13: =N13 -> 45722 | S13: Evolution | U13: =Q13 -> 46082 | V13: =R13 -> 45722 | W13: Evolution | Z13: T3 auto | AD13: PP T3 | AF13: EDM | AI13: REV
B16: SOFAC | E16: =SOFAC!$B$11 -> 2870929.1 | F16: =SOFAC!$C$11 -> 2374846.4 | G16: =IF(F16=0,0,E16/F16-1) -> 0.20889044 | I16: =SOFAC!$B$23 -> 427944.8 | J16: =SOFAC!$C$23 -> 365996.14 | K16: =IF(J16=0,0,I16/J16-1) -> 0.16926044 | M16: =SOFAC!$B$18 -> 1143.1023 | N16: =SOFAC!$C$18 -> 2242.694 | O16: =IF(N16=0,0,M16/N16-1) -> -0.49029948 | Q16: =SOFAC!$B$28 -> 0 | R16: =SOFAC!$C$28 -> 0 | S16: =IF(R16=0,0,Q16/R16-1) -> 0 | U16: =Q16+M16+I16+E16 -> 3300017 | V16: =R16+N16+J16+F16 -> 2743085.2 | W16: =IF(V16=0,0,U16/V16-1) -> 0.20303116 | Z16: =E18-'Syn prin concurents'!E16 -> -1460556.5 | AA16: =+Z16+AD16 -> -1226115.5 | AD16: =I18-'Syn prin concurents'!I16 -> 234440.97 | AG16: =M18-'Syn prin concurents'!M16 -> 258152.24 | AI16: =Q18-'Syn prin concurents'!Q16 -> 4779.046 | AJ16: =W18-'Syn prin concurents'!W16 -> -0.17772533 | AL16: =U18-'Syn prin concurents'!U16 -> -963184.22
B17: Part de marché | E17: =E16/E$30 -> 0.41255608 | F17: =F16/F$30 -> 0.36887057 | G17: =(E17-F17)*100 -> 4.3685512 | I17: =I16/I$30 -> 0.23907391 | J17: =J16/J$30 -> 0.17667436 | K17: =(I17-J17)*100 -> 6.2399545 | M17: =M16/M$30 -> 0.0043862611 | N17: =N16/N$30 -> 0.013531753 | O17: =(M17-N17)*100 -> -0.91454916 | Q17: =Q16/Q$30 -> 0 | R17: =R16/R$30 -> 0 | S17: =(Q17-R17)*100 -> 0 | U17: =U16/U$30 -> 0.36603717 | V17: =V16/V$30 -> 0.31597208 | W17: =(U17-V17)*100 -> 5.0065088
B18: WAFASALAF | E18: =WAFASALAF!$B$11 -> 1410372.7 | F18: =WAFASALAF!$C$11 -> 1394520.5 | G18: =IF(F18=0,0,E18/F18-1) -> 0.011367451 | I18: =WAFASALAF!$B$23 -> 662385.77 | J18: =WAFASALAF!$C$23 -> 716594.4 | K18: =IF(J18=0,0,I18/J18-1) -> -0.075647575 | M18: =WAFASALAF!$B$18 -> 259295.34 | N18: =WAFASALAF!$C$18 -> 162726.73 | O18: =IF(N18=0,0,M18/N18-1) -> 0.59344032 | Q18: =WAFASALAF!$B$28 -> 4779.046 | R18: =WAFASALAF!$C$28 -> 5315.21 | S18: =IF(R18=0,0,Q18/R18-1) -> -0.10087353 | U18: =Q18+M18+I18+E18 -> 2336832.8 | V18: =R18+N18+J18+F18 -> 2279156.9 | W18: =IF(V18=0,0,U18/V18-1) -> 0.02530583 | Z18: =E16-'Syn prin concurents'!E18 -> 1460556.5 | AA18: =+Z18+AD18 -> 1226115.5 | AD18: =I16-'Syn prin concurents'!I18 -> -234440.97 | AG18: =M16-'Syn prin concurents'!M18 -> -258152.24 | AI18: =Q16-'Syn prin concurents'!Q18 -> -4779.046 | AL18: =U16-'Syn prin concurents'!U18 -> 963184.22
B19: Part de marché | E19: =E18/E$30 -> 0.2026723 | F19: =F18/F$30 -> 0.21660246 | G19: =(E19-F19)*100 -> -1.3930157 | I19: =I18/I$30 -> 0.37004575 | J19: =J18/J$30 -> 0.34591583 | K19: =(I19-J19)*100 -> 2.4129914 | M19: =M18/M$30 -> 0.99495651 | N19: =N18/N$30 -> 0.98184502 | O19: =(M19-N19)*100 -> 1.3111489 | Q19: =Q18/Q$30 -> 0.79358885 | R19: =R18/R$30 -> 0.89505428 | S19: =(Q19-R19)*100 -> -10.146543 | U19: =U18/U$30 -> 0.25920099 | V19: =V18/V$30 -> 0.26253283 | W19: =(U19-V19)*100 -> -0.33318452
B20: VIVALIS | E20: =VIVALIS!$B$11 -> 781065.78 | F20: =VIVALIS!$C$11 -> 1034282.2 | G20: =IF(F20=0,0,E20/F20-1) -> -0.24482334 | I20: =VIVALIS!$B$23 -> 212657.49 | J20: =VIVALIS!$C$23 -> 324761.03 | K20: =IF(J20=0,0,I20/J20-1) -> -0.34518778 | M20: =VIVALIS!$B$18 -> 0 | N20: =VIVALIS!$C$18 -> 0 | O20: =IF(N20=0,0,M20/N20-1) -> 0 | Q20: =VIVALIS!$B$28 -> 0 | R20: =VIVALIS!$C$28 -> 0 | S20: =IF(R20=0,0,Q20/R20-1) -> 0 | U20: =Q20+M20+I20+E20 -> 993723.27 | V20: =R20+N20+J20+F20 -> 1359043.2 | W20: =IF(V20=0,0,U20/V20-1) -> -0.26880673 | Z20: =E20-'Syn prin concurents'!E20 -> 0 | AA20: =+Z20+AD20 -> 0 | AD20: =I20-'Syn prin concurents'!I20 -> 0 | AG20: =M20-'Syn prin concurents'!M20 -> 0 | AI20: =Q20-'Syn prin concurents'!Q20 -> 0 | AL20: =U20-'Syn prin concurents'!U20 -> 0
B21: Part de marché | E21: =E20/E$30 -> 0.11224012 | F21: =F20/F$30 -> 0.16064882 | G21: =(E21-F21)*100 -> -4.8408693 | I21: =I20/I$30 -> 0.11880237 | J21: =J20/J$30 -> 0.15676927 | K21: =(I21-J21)*100 -> -3.79669 | M21: =M20/M$30 -> 0 | N21: =N20/N$30 -> 0 | O21: =(M21-N21)*100 -> 0 | Q21: =Q20/Q$30 -> 0 | R21: =R20/R$30 -> 0 | S21: =(Q21-R21)*100 -> 0 | U21: =U20/U$30 -> 0.11022357 | V21: =V20/V$30 -> 0.15654625 | W21: =(U21-V21)*100 -> -4.6322685
B22: EQDOM | E22: =EQDOM!$B$11 -> 655331.21 | F22: =EQDOM!$C$11 -> 543784.17 | G22: =IF(F22=0,0,E22/F22-1) -> 0.20513108 | I22: =EQDOM!$B$23 -> 284808.22 | J22: =EQDOM!$C$23 -> 375445.19 | K22: =IF(J22=0,0,I22/J22-1) -> -0.24141199 | M22: =EQDOM!$B$18 -> 171.281 | N22: =EQDOM!$C$18 -> 766.234 | O22: =IF(N22=0,0,M22/N22-1) -> -0.77646385 | Q22: =EQDOM!$B$28 -> 0 | R22: =EQDOM!$C$28 -> 0 | S22: =IF(R22=0,0,Q22/R22-1) -> 0 | U22: =Q22+M22+I22+E22 -> 940310.71 | V22: =R22+N22+J22+F22 -> 919995.59 | W22: =IF(V22=0,0,U22/V22-1) -> 0.022081753
B23: Part de marché | E23: =E22/E$30 -> 0.094171908 | F23: =F22/F$30 -> 0.084462715 | G23: =(E23-F23)*100 -> 0.97091932 | I23: =I22/I$30 -> 0.1591098 | J23: =J22/J$30 -> 0.18123563 | K23: =(I23-J23)*100 -> -2.2125822 | M23: =M22/M$30 -> 0.00065723181 | N23: =N22/N$30 -> 0.0046232295 | O23: =(M23-N23)*100 -> -0.39659977 | Q23: =Q22/Q$30 -> 0 | R23: =R22/R$30 -> 0 | S23: =(Q23-R23)*100 -> 0 | U23: =U22/U$30 -> 0.10429906 | V23: =V22/V$30 -> 0.10597298 | W23: =(U23-V23)*100 -> -0.16739229
B24: RCI | E24: ='RCI '!$B$11 -> 878735.06 | F24: ='RCI '!$C$11 -> 776137.95 | G24: =IF(F24=0,0,E24/F24-1) -> 0.13218927 | I24: ='RCI '!$B$23 -> 0 | J24: ='RCI '!$C$23 -> 0 | K24: =IF(J24=0,0,I24/J24-1) -> 0 | M24: ='RCI '!$B$18 -> 0 | N24: ='RCI '!$C$18 -> 0 | O24: =IF(N24=0,0,M24/N24-1) -> 0 | Q24: ='RCI '!$B$28 -> 0 | R24: ='RCI '!$C$28 -> 0 | S24: =IF(R24=0,0,Q24/R24-1) -> 0 | U24: =Q24+M24+I24+E24 -> 878735.06 | V24: =R24+N24+J24+F24 -> 776137.95 | W24: =IF(V24=0,0,U24/V24-1) -> 0.13218927
B25: Part de marché | E25: =E24/E$30 -> 0.12627532 | F25: =F24/F$30 -> 0.12055283 | G25: =(E25-F25)*100 -> 0.57224939 | I25: =I24/I$30 -> 0 | J25: =J24/J$30 -> 0 | K25: =(I25-J25)*100 -> 0 | M25: =M24/M$30 -> 0 | N25: =N24/N$30 -> 0 | O25: =(M25-N25)*100 -> 0 | Q25: =Q24/Q$30 -> 0 | R25: =R24/R$30 -> 0 | S25: =(Q25-R25)*100 -> 0 | U25: =U24/U$30 -> 0.097469101 | V25: =V24/V$30 -> 0.089402225 | W25: =(U25-V25)*100 -> 0.80668769
B26: SALAFIN | E26: =SALAFIN!B11 -> 151024.44 | F26: =SALAFIN!C11 -> 142561.56 | G26: =IF(F26=0,0,E26/F26-1) -> 0.059362974 | I26: =SALAFIN!B23 -> 100851.57 | J26: =SALAFIN!C23 -> 126212.98 | K26: =IF(J26=0,0,I26/J26-1) -> -0.20094135 | M26: =SALAFIN!$B$18 -> 0 | N26: =SALAFIN!$C$18 -> 0 | O26: =IF(N26=0,0,M26/N26-1) -> 0 | Q26: =SALAFIN!$B$28 -> 1243.022 | R26: =SALAFIN!$C$28 -> 623.212 | S26: =IF(R26=0,0,Q26/R26-1) -> 0.99454118 | U26: =Q26+M26+I26+E26 -> 253119.03 | V26: =R26+N26+J26+F26 -> 269397.75 | W26: =IF(V26=0,0,U26/V26-1) -> -0.060426333
B27: Part de marché | E27: =E26/E$30 -> 0.021702399 | F27: =F26/F$30 -> 0.022143227 | G27: =(E27-F27)*100 -> -0.044082783 | I27: =I26/I$30 -> 0.056341329 | J27: =J26/J$30 -> 0.060925772 | K27: =(I27-J27)*100 -> -0.45844427 | M27: =M26/M$30 -> 0 | N27: =N26/N$30 -> 0 | O27: =(M27-N27)*100 -> 0 | Q27: =Q26/Q$30 -> 0.20641115 | R27: =R26/R$30 -> 0.10494572 | S27: =(Q27-R27)*100 -> 10.146543 | U27: =U26/U$30 -> 0.028075907 | V27: =V26/V$30 -> 0.031031543 | W27: =(U27-V27)*100 -> -0.29556352
B28: AXA | E28: ='AXA CREDIT'!$B$11 -> 935.296 | F28: ='AXA CREDIT'!$C$11 -> 3021.509 | G28: =IF(F28=0,0,E28/F28-1) -> -0.69045401 | I28: ='AXA CREDIT'!$B$23 -> 93308.449 | J28: ='AXA CREDIT'!$C$23 -> 151048.95 | K28: =IF(J28=0,0,I28/J28-1) -> -0.38226352 | M28: ='AXA CREDIT'!$B$18 -> 0 | N28: ='AXA CREDIT'!$C$18 -> 0 | O28: =IF(N28=0,0,M28/N28-1) -> 0 | Q28: ='AXA CREDIT'!$B$28 -> 0 | R28: ='AXA CREDIT'!$C$28 -> 0 | S28: =IF(R28=0,0,Q28/R28-1) -> 0 | U28: =Q28+M28+I28+E28 -> 94243.745 | V28: =R28+N28+J28+F28 -> 154070.46 | W28: =IF(V28=0,0,U28/V28-1) -> -0.38830751
B29: Part de marché | E29: =E28/E$30 -> 0.0001344032 | F29: =F28/F$30 -> 0.00046931276 | G29: =(E29-F29)*100 -> -0.033490957 | I29: =I28/I$30 -> 0.052127319 | J29: =J28/J$30 -> 0.072914642 | K29: =(I29-J29)*100 -> -2.0787323 | M29: =M28/M$30 -> 0 | N29: =N28/N$30 -> 0 | O29: =(M29-N29)*100 -> 0 | Q29: =Q28/Q$30 -> 0 | R29: =R28/R$30 -> 0 | S29: =(Q29-R29)*100 -> 0 | U29: =U28/U$30 -> 0.010453496 | V29: =V28/V$30 -> 0.017747157 | W29: =(U29-V29)*100 -> -0.72936613
B30: Marché | E30: =GLOBAL!$B$11 -> 6958882.1 | F30: =GLOBAL!$C$11 -> 6438156.4 | G30: =IF(F30=0,0,E30/F30-1) -> 0.080881179 | I30: =GLOBAL!$B$23 -> 1790010.5 | J30: =GLOBAL!$C$23 -> 2071586 | K30: =IF(J30=0,0,I30/J30-1) -> -0.13592267 | M30: =GLOBAL!$B$18 -> 260609.72 | N30: =GLOBAL!$C$18 -> 165735.66 | O30: =IF(N30=0,0,M30/N30-1) -> 0.57244204 | Q30: =GLOBAL!$B$28 -> 6022.068 | R30: =GLOBAL!$C$28 -> 5938.422 | S30: =IF(R30=0,0,Q30/R30-1) -> 0.01408556 | U30: =Q30+M30+I30+E30 -> 9015524.4 | V30: =R30+N30+J30+F30 -> 8681416.5 | W30: =IF(V30=0,0,U30/V30-1) -> 0.038485411
B33: Encours Sain
E35: Vehicules (en MDH): | I35: Prêts personnels (en MDH) | M35: Equipement domestique (en MDH) | Q35: Revolving (en MDH) | U35: Global (en MDH)
E37: =E13 -> 46082 | F37: 45992 | G37: Evolution | I37: =E37 -> 46082 | J37: =F37 -> 45992 | K37: Evolution | M37: =I37 -> 46082 | N37: =J37 -> 45992 | O37: Evolution | Q37: =M37 -> 46082 | R37: =N37 -> 45992 | S37: Evolution | U37: =Q37 -> 46082 | V37: =R37 -> 45992 | W37: Evolution
B40: WAFASALAF | E40: =WAFASALAF!$B$41 -> 15684752 | F40: =+'[2]Syn prin concurents'!$E$40 -> 14963780 | G40: =IF(F40=0,0,E40/F40-1) -> 0.048181104 | I40: =WAFASALAF!$B$50 -> 8793278.6 | J40: =+'[2]Syn prin concurents'!$I$40 -> 8793162.5 | K40: =IF(J40=0,0,I40/J40-1) -> 1.3206398e-05 | M40: =WAFASALAF!$B$48-WAFASALAF!$B$41 -> 605147.41 | N40: ='[2]Syn prin concurents'!$M$40 -> 526530.19 | O40: =IF(N40=0,0,M40/N40-1) -> 0.1493119 | Q40: =WAFASALAF!$B$55 -> 74028.192 | R40: ='[2]Syn prin concurents'!$Q$40 -> 75392.82 | S40: =IF(R40=0,0,Q40/R40-1) -> -0.018100238 | U40: =Q40+M40+I40+E40 -> 25157206 | V40: =R40+N40+J40+F40 -> 24358866 | W40: =IF(V40=0,0,U40/V40-1) -> 0.032774111 | Z40: =E40-'Syn prin concurents'!E40 -> 0 | AD40: =I40-'Syn prin concurents'!I40 -> 0 | AG40: =M40-'Syn prin concurents'!M40 -> 0 | AI40: =Q40-'Syn prin concurents'!Q40 -> 0 | AJ40: =W40-'Syn prin concurents'!W40 -> 0 | AL40: =U40-'Syn prin concurents'!U40 -> 0
B41: Part de marché | E41: =E40/E$54 -> 0.27809813 | F41: =F40/F$54 -> 0.28058151 | G41: =(E41-F41)*100 -> -0.24833773 | I41: =I40/I$54 -> 0.33905709 | J41: =J40/J$54 -> 0.33819791 | K41: =(I41-J41)*100 -> 0.085917861 | M41: =M40/M$54 -> 0.99022624 | N41: =N40/N$54 -> 0.98782547 | O41: =(M41-N41)*100 -> 0.24007765 | Q41: =Q40/Q$54 -> 0.32790682 | R41: =R40/R$54 -> 0.43523822 | S41: =(Q41-R41)*100 -> -10.73314 | U41: =U40/U$54 -> 0.30247406 | V41: =V40/V$54 -> 0.30434276 | W41: =(U41-V41)*100 -> -0.18687048
B42: SOFAC | E42: =SOFAC!B41 -> 15645979 | F42: =+[2]SOFAC!$B$41 -> 13709550 | G42: =IF(F42=0,0,E42/F42-1) -> 0.14124669 | I42: =SOFAC!B50 -> 3875022.7 | J42: =+'[2]Syn prin concurents'!$I$42 -> 3748985.8 | K42: =IF(J42=0,0,I42/J42-1) -> 0.033618935 | M42: =SOFAC!B48-SOFAC!B41 -> 4423.4979 | N42: ='[2]Syn prin concurents'!$M$42 -> 4639.6442 | O42: =IF(N42=0,0,M42/N42-1) -> -0.046586831 | Q42: =SOFAC!B55 -> 0 | R42: ='[2]Syn prin concurents'!$Q$42 -> 0 | S42: =IF(R42=0,0,Q42/R42-1) -> 0 | U42: =Q42+M42+I42+E42 -> 19525425 | V42: =R42+N42+J42+F42 -> 17463175 | W42: =IF(V42=0,0,U42/V42-1) -> 0.11809131 | Z42: =E42-'Syn prin concurents'!E42 -> 0 | AD42: =I42-'Syn prin concurents'!I42 -> 0 | AG42: =M42-'Syn prin concurents'!M42 -> 0 | AI42: =Q42-'Syn prin concurents'!Q42 -> 0 | AL42: =U42-'Syn prin concurents'!U42 -> 0
B43: Part de marché | E43: =E42/E$54 -> 0.27741067 | F43: =F42/F$54 -> 0.2570638 | G43: =(E43-F43)*100 -> 2.0346865 | I43: =I42/I$54 -> 0.1494157 | J43: =J42/J$54 -> 0.14419149 | K43: =(I43-J43)*100 -> 0.52242189 | M43: =M42/M$54 -> 0.0072383416 | N43: =N42/N$54 -> 0.0087044557 | O43: =(M43-N43)*100 -> -0.14661141 | Q43: =Q42/Q$54 -> 0 | R43: =R42/R$54 -> 0 | S43: =(Q43-R43)*100 -> 0 | U43: =U42/U$54 -> 0.23476115 | V43: =V42/V$54 -> 0.21818713 | W43: =(U43-V43)*100 -> 1.6574013
B44: VIVALIS | E44: =VIVALIS!B41 -> 10896178 | F44: =+'[2]Syn prin concurents'!$E$44 -> 11314645 | G44: =IF(F44=0,0,E44/F44-1) -> -0.036984497 | I44: =VIVALIS!B50 -> 5436494 | J44: =+'[2]Syn prin concurents'!$I$44 -> 5668706.6 | K44: =IF(J44=0,0,I44/J44-1) -> -0.040963953 | M44: =VIVALIS!$B$48-VIVALIS!$B$41 -> 0 | N44: ='[2]Syn prin concurents'!$M$44 -> 0 | O44: =IF(N44=0,0,M44/N44-1) -> 0 | Q44: =VIVALIS!$B$55 -> 0 | R44: ='[2]Syn prin concurents'!$Q$44 -> 0 | S44: =IF(R44=0,0,Q44/R44-1) -> 0 | U44: =Q44+M44+I44+E44 -> 16332672 | V44: =R44+N44+J44+F44 -> 16983351 | W44: =IF(V44=0,0,U44/V44-1) -> -0.038312761 | Z44: =E44-'Syn prin concurents'!E44 -> 0 | AD44: =I44-'Syn prin concurents'!I44 -> 0 | AG44: =M44-'Syn prin concurents'!M44 -> 0 | AI44: =Q44-'Syn prin concurents'!Q44 -> 0 | AL44: =U44-'Syn prin concurents'!U44 -> 0
B45: Part de marché | E45: =E44/E$54 -> 0.19319444 | F45: =F44/F$54 -> 0.21215763 | G45: =(E45-F45)*100 -> -1.8963186 | I45: =I44/I$54 -> 0.20962395 | J45: =J44/J$54 -> 0.21802676 | K45: =(I45-J45)*100 -> -0.84028073 | M45: =M44/M$54 -> 0 | N45: =N44/N$54 -> 0 | O45: =(M45-N45)*100 -> 0 | Q45: =Q44/Q$54 -> 0 | R45: =R44/R$54 -> 0 | S45: =(Q45-R45)*100 -> 0 | U45: =U44/U$54 -> 0.19637354 | V45: =V44/V$54 -> 0.21219215 | W45: =(U45-V45)*100 -> -1.5818606
B46: EQDOM | E46: =EQDOM!$B$41 -> 5309762.3 | F46: =+'[2]Syn prin concurents'!$E$46 -> 4911209.1 | G46: =IF(F46=0,0,E46/F46-1) -> 0.081151767 | I46: =EQDOM!$B$50 -> 4681801.3 | J46: =+'[2]Syn prin concurents'!$I$46 -> 4707307.4 | K46: =IF(J46=0,0,I46/J46-1) -> -0.0054183982 | M46: =EQDOM!$B$48-EQDOM!$B$41 -> 1549.444 | N46: ='[2]Syn prin concurents'!$M$46 -> 1849.619 | O46: =IF(N46=0,0,M46/N46-1) -> -0.16229018 | Q46: =EQDOM!$B$55 -> 0 | R46: ='[2]Syn prin concurents'!$Q$46 -> 0 | S46: =IF(R46=0,0,Q46/R46-1) -> 0 | U46: =Q46+M46+I46+E46 -> 9993113.1 | V46: =R46+N46+J46+F46 -> 9620366 | W46: =IF(V46=0,0,U46/V46-1) -> 0.03874562
B47: Part de marché | E47: =E46/E$54 -> 0.09414462 | F47: =F46/F$54 -> 0.092088659 | G47: =(E47-F47)*100 -> 0.20559616 | I47: =I46/I$54 -> 0.18052401 | J47: =J46/J$54 -> 0.18104994 | K47: =(I47-J47)*100 -> -0.052592661 | M47: =M46/M$54 -> 0.0025354155 | N47: =N46/N$54 -> 0.0034700779 | O47: =(M47-N47)*100 -> -0.09346624 | Q47: =Q46/Q$54 -> 0 | R47: =R46/R$54 -> 0 | S47: =(Q47-R47)*100 -> 0 | U47: =U46/U$54 -> 0.12015076 | V47: =V46/V$54 -> 0.12019808 | W47: =(U47-V47)*100 -> -0.0047313007
B48: RCI | E48: ='RCI '!$B$41 -> 6280424.6 | F48: =+'[2]Syn prin concurents'!$E$48 -> 6050871.8 | G48: =IF(F48=0,0,E48/F48-1) -> 0.037937141 | I48: ='RCI '!$B$50 -> 0 | J48: =+'[2]Syn prin concurents'!$I$48 -> 0 | K48: =IF(J48=0,0,I48/J48-1) -> 0 | M48: ='RCI '!$B$48-'RCI '!$B$41 -> 0 | N48: ='[2]Syn prin concurents'!$M$48 -> 0 | O48: =IF(N48=0,0,M48/N48-1) -> 0 | Q48: ='RCI '!$B$55 -> 0 | R48: ='[2]Syn prin concurents'!$Q$48 -> 0 | S48: =IF(R48=0,0,Q48/R48-1) -> 0 | U48: =Q48+M48+I48+E48 -> 6280424.6 | V48: =R48+N48+J48+F48 -> 6050871.8 | W48: =IF(V48=0,0,U48/V48-1) -> 0.037937141
B49: Part de marché | E49: =E48/E$54 -> 0.11135493 | F49: =F48/F$54 -> 0.11345815 | G49: =(E49-F49)*100 -> -0.21032199 | I49: =I48/I$54 -> 0 | J49: =J48/J$54 -> 0 | K49: =(I49-J49)*100 -> 0 | M49: =M48/M$54 -> 0 | N49: =N48/N$54 -> 0 | O49: =(M49-N49)*100 -> 0 | Q49: =Q48/Q$54 -> 0 | R49: =R48/R$54 -> 0 | S49: =(Q49-R49)*100 -> 0 | U49: =U48/U$54 -> 0.075511785 | V49: =V48/V$54 -> 0.075600362 | W49: =(U49-V49)*100 -> -0.0088576557
B50: SALAFIN | E50: =SALAFIN!B41 -> 1394923.7 | F50: =+'[2]Syn prin concurents'!$E$50 -> 1323553.5 | G50: =IF(F50=0,0,E50/F50-1) -> 0.053923197 | I50: =SALAFIN!B50 -> 959308.06 | J50: =+'[2]Syn prin concurents'!$I$50 -> 891751.11 | K50: =IF(J50=0,0,I50/J50-1) -> 0.075757637 | M50: =SALAFIN!$B$48-SALAFIN!$B$41 -> 0 | N50: ='[2]Syn prin concurents'!$M$50 -> 0 | O50: =IF(N50=0,0,M50/N50-1) -> 0 | Q50: =SALAFIN!$B$55 -> 151731.65 | R50: ='[2]Syn prin concurents'!$Q$50 -> 97829.146 | S50: =IF(R50=0,0,Q50/R50-1) -> 0.55098617 | U50: =Q50+M50+I50+E50 -> 2505963.4 | V50: =R50+N50+J50+F50 -> 2313133.7 | W50: =IF(V50=0,0,U50/V50-1) -> 0.08336297
B51: Part de marché | E51: =E50/E$54 -> 0.024732663 | F51: =F50/F$54 -> 0.024817568 | G51: =(E51-F51)*100 -> -0.0084904849 | I51: =I50/I$54 -> 0.036989638 | J51: =J50/J$54 -> 0.034298054 | K51: =(I51-J51)*100 -> 0.26915849 | M51: =M50/M$54 -> 0 | N51: =N50/N$54 -> 0 | O51: =(M51-N51)*100 -> 0 | Q51: =Q50/Q$54 -> 0.67209318 | R51: =R50/R$54 -> 0.56476178 | S51: =(Q51-R51)*100 -> 10.73314 | U51: =U50/U$54 -> 0.030130092 | V51: =V50/V$54 -> 0.028900587 | W51: =(U51-V51)*100 -> 0.12295053
B52: AXA | E52: ='AXA CREDIT'!$B$41 -> 13470.115 | F52: =+'[2]Syn prin concurents'!$E$52 -> 13470.115 | G52: =IF(F52=0,0,E52/F52-1) -> 0 | I52: ='AXA CREDIT'!$B$50 -> 2167039.3 | J52: =+'[2]Syn prin concurents'!$I$52 -> 2167039.3 | K52: =IF(J52=0,0,I52/J52-1) -> 0 | N52: ='[3]Syn prin concurents'!M52 -> 0 | O52: =IF(N52=0,0,M52/N52-1) -> 0 | Q52: ='AXA CREDIT'!$B$55 -> 0 | R52: ='[2]Syn prin concurents'!$Q$52 -> 0 | S52: =IF(R52=0,0,Q52/R52-1) -> 0 | U52: =Q52+M52+I52+E52 -> 2180509.4 | V52: =R52+N52+J52+F52 -> 2180509.4 | W52: =IF(V52=0,0,U52/V52-1) -> 0
B53: Part de marché | E53: =E52/E$54 -> 0.00023883157 | F53: =F52/F$54 -> 0.00025257423 | G53: =(E53-F53)*100 -> -0.0013742658 | I53: =I52/I$54 -> 0.083558143 | J53: =J52/J$54 -> 0.083347505 | K53: =(I53-J53)*100 -> 0.021063759 | M53: =M52/M$54 -> 0 | N53: =N52/N$54 -> 0 | O53: =(M53-N53)*100 -> 0 | Q53: =Q52/Q$54 -> 0 | R53: =R52/R$54 -> 0 | S53: =(Q53-R53)*100 -> 0 | U53: =U52/U$54 -> 0.026217042 | V53: =V52/V$54 -> 0.027243562 | W53: =(U53-V53)*100 -> -0.10265193
B54: Marché | D54: ='[4]global '!$E$11 -> 3701705 | E54: =GLOBAL!B41 -> 56400061 | F54: =+'[2]Syn prin concurents'!$E$54 -> 53331313 | G54: =IF(F54=0,0,E54/F54-1) -> 0.057541214 | I54: =GLOBAL!B51+GLOBAL!B52+GLOBAL!B53+GLOBAL!B54 -> 25934508 | J54: =+'[2]Syn prin concurents'!$I$54 -> 26000050 | K54: =IF(J54=0,0,I54/J54-1) -> -0.0025208505 | M54: =GLOBAL!B48-GLOBAL!B41 -> 611120.35 | N54: ='[2]Syn prin concurents'!$M$54 -> 533019.45 | O54: =IF(N54=0,0,M54/N54-1) -> 0.14652543 | Q54: =GLOBAL!B55 -> 225759.84 | R54: ='[2]Syn prin concurents'!$Q$54 -> 173221.97 | S54: =IF(R54=0,0,Q54/R54-1) -> 0.30329801 | U54: =Q54+M54+I54+E54 -> 83171449 | V54: =R54+N54+J54+F54 -> 80037604 | W54: =IF(V54=0,0,U54/V54-1) -> 0.039154658
B57: Créances en souffrances
E59: Vehicules (en MDH): | I59: Prêts personnels (en MDH) | M59: Equipement domestique (en MDH) | Q59: Revolving (en MDH) | U59: Global (en MDH)
E61: =E37 -> 46082 | F61: =F37 -> 45992 | G61: Evolution | I61: =E61 -> 46082 | J61: =F61 -> 45992 | K61: Evolution | M61: =I61 -> 46082 | N61: =J61 -> 45992 | O61: Evolution | Q61: =M61 -> 46082 | R61: =N61 -> 45992 | S61: Evolution | U61: =Q61 -> 46082 | V61: =R61 -> 45992 | W61: Evolution | Z61: =U64/U87 -> 0.1041468 | AA61: =+'Syn prin concurents'!E64 -> 1355921.4
...

Sheet Syn prin concurents par catégor
A2: =C13 -> 46082
A9: Production nette
C11: Auto Classiques (En MDH) | G11: LOA (en MDH) | K11: Fonctionnaires (en MDH) | O11: Retraités (en MDH) | S11: Conventions (en MDH) | W11: Bancaires (en MDH) | AA11: Equipement domestique (en MDH) | AE11: Revolving (en MDH) | AI11: Global (en MDH)
C13: 46082 | D13: =C13-360 -> 45722 | E13: Evolution | G13: =C13 -> 46082 | H13: =G13-360 -> 45722 | I13: Evolution | K13: =G13 -> 46082 | L13: =H13 -> 45722 | M13: Evolution | O13: =K13 -> 46082 | P13: =L13 -> 45722 | Q13: Evolution | S13: =O13 -> 46082 | T13: =P13 -> 45722 | U13: Evolution | W13: =S13 -> 46082 | X13: =T13 -> 45722 | Y13: Evolution | AA13: =K13 -> 46082 | AB13: =L13 -> 45722 | AC13: Evolution | AE13: =AA13 -> 46082 | AF13: =AB13 -> 45722 | AG13: Evolution | AI13: =AE13 -> 46082 | AJ13: =AF13 -> 45722 | AK13: Evolution | AL13: AUTO | AN13: PP | AP13: EDM | AR13: REVOLVING | AT13: GLOBAL
A16: WAFASALAF | C16: =WAFASALAF!$B$12 -> 459172.33 | D16: =WAFASALAF!$C$12 -> 467803.11 | E16: =IF(D16=0,0,C16/D16-1) -> -0.018449601 | G16: =WAFASALAF!$B$13 -> 951200.32 | H16: =WAFASALAF!$C$13 -> 926717.4 | I16: =IF(H16=0,0,G16/H16-1) -> 0.026418976 | K16: =WAFASALAF!$B$24 -> 270125.24 | L16: =WAFASALAF!$C$24 -> 365425.54 | M16: =IF(L16=0,0,K16/L16-1) -> -0.26079267 | O16: =WAFASALAF!$B$25 -> 62934.633 | P16: =WAFASALAF!$C$25 -> 69721.446 | Q16: =IF(P16=0,0,O16/P16-1) -> -0.097341828 | S16: =WAFASALAF!$B$26 -> 22798.366 | T16: =WAFASALAF!$C$26 -> 27255.566 | U16: =IF(T16=0,0,S16/T16-1) -> -0.16353357 | W16: =WAFASALAF!$B$27 -> 306527.53 | X16: =WAFASALAF!$C$27 -> 254191.85 | Y16: =IF(X16=0,0,W16/X16-1) -> 0.2058905 | AA16: =WAFASALAF!$B$18 -> 259295.34 | AB16: =WAFASALAF!$C$18 -> 162726.73 | AC16: =IF(AB16=0,0,AA16/AB16-1) -> 0.59344032 | AE16: =WAFASALAF!$B$28 -> 4779.046 | AF16: =WAFASALAF!$C$28 -> 5315.21 | AG16: =IF(AF16=0,0,AE16/AF16-1) -> -0.10087353 | AI16: =AE16+AA16+K16+G16+C16+O16+S16+W16 -> 2336832.8 | AJ16: =AF16+AB16+L16+H16+D16+P16+T16+X16 -> 2279156.9 | AK16: =IF(AJ16=0,0,AI16/AJ16-1) -> 0.02530583 | AL16: =C16+G16-'Syn prin concurents'!E18 -> 0 | AM16: =D16+H16-'Syn prin concurents'!F18 -> 0 | AN16: =K16+O16+S16+W16-'Syn prin concurents'!I18 -> 0 | AO16: =L16+P16+T16+X16-'Syn prin concurents'!J18 -> 0 | AP16: =AA16-'Syn prin concurents'!M18 -> 0 | AQ16: =AB16-'Syn prin concurents'!N18 -> 0 | AR16: =AE16-'Syn prin concurents'!Q18 -> 0 | AS16: =AF16-'Syn prin concurents'!R18 -> 0 | AT16: =AI16-'Syn prin concurents'!U18 -> 0 | AU16: =AJ16-'Syn prin concurents'!V18 -> 0
A17: Part de marché | C17: =C16/C$30 -> 0.13308895 | D17: =D16/D$30 -> 0.14882279 | E17: =(C17-D17)*100 -> -1.5733844 | G17: =G16/G$30 -> 0.27109255 | H17: =H16/H$30 -> 0.28130835 | I17: =(G17-H17)*100 -> -1.0215802 | K17: =K16/K$30 -> 0.36148922 | L17: =L16/L$30 -> 0.31891332 | M17: =(K17-L17)*100 -> 4.2575906 | O17: =O16/O$30 -> 0.3243048 | P17: =P16/P$30 -> 0.32513034 | Q17: =(O17-P17)*100 -> -0.082554191 | S17: =S16/S$30 -> 0.46577672 | T17: =T16/T$30 -> 0.41623746 | U17: =(S17-T17)*100 -> 4.9539259 | W17: =W16/W$30 -> 0.38328078 | X17: =X16/X$30 -> 0.39359691 | Y17: =(W17-X17)*100 -> -1.0316132 | AA17: =AA16/AA$30 -> 0.99495651 | AB17: =AB16/AB$30 -> 0.98184502 | AC17: =(AA17-AB17)*100 -> 1.3111489 | AE17: =AE16/AE$30 -> 0.79358885 | AF17: =AF16/AF$30 -> 0.89505428 | AG17: =(AE17-AF17)*100 -> -10.146543 | AI17: =AI16/AI$30 -> 0.25920099 | AJ17: =AJ16/AJ$30 -> 0.26254759 | AK17: =(AI17-AJ17)*100 -> -0.33466073 | AL17: =C17+G17-'Syn prin concurents'!E19 -> 0.2015092 | AM17: =D17+H17-'Syn prin concurents'!F19 -> 0.21352869 | AN17: =K17+O17+S17+W17-'Syn prin concurents'!I19 -> 1.1648058 | AO17: =L17+P17+T17+X17-'Syn prin concurents'!J19 -> 1.1079622 | AP17: =AA17-'Syn prin concurents'!M19 -> 0 | AQ17: =AB17-'Syn prin concurents'!N19 -> 0 | AR17: =AE17-'Syn prin concurents'!Q19 -> 0 | AS17: =AF17-'Syn prin concurents'!R19 -> 0 | AT17: =AI17-'Syn prin concurents'!U19 -> 0 | AU17: =AJ17-'Syn prin concurents'!V19 -> 1.4762112e-05
A18: SOFAC | C18: =SOFAC!$B$12 -> 1477587.7 | D18: =SOFAC!$C$12 -> 1209540.1 | E18: =IF(D18=0,0,C18/D18-1) -> 0.22161122 | G18: =SOFAC!$B$13 -> 1393341.4 | H18: =SOFAC!$C$13 -> 1165306.4 | I18: =IF(H18=0,0,G18/H18-1) -> 0.19568679 | K18: =SOFAC!$B$24 -> 69775.159 | L18: =SOFAC!$C$24 -> 94865.973 | M18: =IF(L18=0,0,K18/L18-1) -> -0.26448697 | O18: =SOFAC!$B$25 -> 56340.571 | P18: =SOFAC!$C$25 -> 58514.492 | Q18: =IF(P18=0,0,O18/P18-1) -> -0.037151835 | S18: =SOFAC!$B$26 -> 715.67446 | T18: =SOFAC!$C$26 -> 1396.0064 | U18: =IF(T18=0,0,S18/T18-1) -> -0.48734157 | W18: =SOFAC!$B$27 -> 301113.4 | X18: =SOFAC!$C$27 -> 211219.67 | Y18: =IF(X18=0,0,W18/X18-1) -> 0.42559358 | AA18: =SOFAC!$B$18 -> 1143.1023 | AB18: =SOFAC!$C$18 -> 2242.694 | AC18: =IF(AB18=0,0,AA18/AB18-1) -> -0.49029948 | AE18: =SOFAC!$B$28 -> 0 | AF18: =SOFAC!$C$28 -> 0 | AG18: =IF(AF18=0,0,AE18/AF18-1) -> 0 | AI18: =AE18+AA18+K18+G18+C18+O18+S18+W18 -> 3300017 | AJ18: =AF18+AB18+L18+H18+D18+P18+T18+X18 -> 2743085.2 | AK18: =IF(AJ18=0,0,AI18/AJ18-1) -> 0.20303116 | AL18: =C18+G18-'Syn prin concurents'!E16 -> 0 | AM18: =D18+H18-'Syn prin concurents'!F16 -> 0 | AN18: =K18+O18+S18+W18-'Syn prin concurents'!I16 -> 0 | AO18: =L18+P18+T18+X18-'Syn prin concurents'!J16 -> 0 | AP18: =AA18-'Syn prin concurents'!M16 -> 0 | AQ18: =AB18-'Syn prin concurents'!N16 -> 0 | AR18: =AE18-'Syn prin concurents'!Q16 -> 0 | AS18: =AF18-'Syn prin concurents'!R16 -> 0 | AT18: =AI18-'Syn prin concurents'!U16 -> 0 | AU18: =AJ18-'Syn prin concurents'!V16 -> 0
A19: Part de marché | C19: =C18/C$30 -> 0.42827187 | D19: =D18/D$30 -> 0.3847925 | E19: =(C19-D19)*100 -> 4.3479374 | G19: =G18/G$30 -> 0.39710298 | H19: =H18/H$30 -> 0.35373288 | I19: =(G19-H19)*100 -> 4.3370097 | K19: =K18/K$30 -> 0.093375086 | L19: =L18/L$30 -> 0.082791207 | M19: =(K19-L19)*100 -> 1.0583879 | O19: =O18/O$30 -> 0.29032532 | P19: =P18/P$30 -> 0.27286922 | Q19: =(O19-P19)*100 -> 1.7456101 | S19: =S18/S$30 -> 0.014621421 | T19: =T18/T$30 -> 0.021319321 | U19: =(S19-T19)*100 -> -0.66979004 | W19: =W18/W$30 -> 0.37651097 | X19: =X18/X$30 -> 0.32705773 | Y19: =(W19-X19)*100 -> 4.9453241 | AA19: =AA18/AA$30 -> 0.0043862611 | AB19: =AB18/AB$30 -> 0.013531753 | AC19: =(AA19-AB19)*100 -> -0.91454916 | AE19: =AE18/AE$30 -> 0 | AF19: =AF18/AF$30 -> 0 | AG19: =(AE19-AF19)*100 -> 0 | AI19: =AI18/AI$30 -> 0.36603717 | AJ19: =AJ18/AJ$30 -> 0.31598985 | AK19: =(AI19-AJ19)*100 -> 5.0047321 | AL19: =C19+G19-'Syn prin concurents'!E17 -> 0.41281877 | AM19: =D19+H19-'Syn prin concurents'!F17 -> 0.36965481 | AN19: =K19+O19+S19+W19-'Syn prin concurents'!I17 -> 0.5357589 | AO19: =L19+P19+T19+X19-'Syn prin concurents'!J17 -> 0.52736312 | AP19: =AA19-'Syn prin concurents'!M17 -> 0 | AQ19: =AB19-'Syn prin concurents'!N17 -> 0 | AR19: =AE19-'Syn prin concurents'!Q17 -> 0 | AS19: =AF19-'Syn prin concurents'!R17 -> 0 | AT19: =AI19-'Syn prin concurents'!U17 -> 0 | AU19: =AJ19-'Syn prin concurents'!V17 -> 1.7766979e-05
A20: VIVALIS | C20: =VIVALIS!$B$12 -> 346945.91 | D20: =VIVALIS!$C$12 -> 544967.06 | E20: =IF(D20=0,0,C20/D20-1) -> -0.36336352 | G20: =VIVALIS!$B$13 -> 434119.87 | H20: =VIVALIS!$C$13 -> 489315.15 | I20: =IF(H20=0,0,G20/H20-1) -> -0.11280108 | K20: =VIVALIS!$B$24 -> 143947.89 | L20: =VIVALIS!$C$24 -> 254226.12 | M20: =IF(L20=0,0,K20/L20-1) -> -0.43378011 | O20: =VIVALIS!$B$25 -> 19747.401 | P20: =VIVALIS!$C$25 -> 30875.489 | Q20: =IF(P20=0,0,O20/P20-1) -> -0.36041819 | S20: =VIVALIS!$B$26 -> 5430.184 | T20: =VIVALIS!$C$26 -> 7455.521 | U20: =IF(T20=0,0,S20/T20-1) -> -0.271656 | W20: =VIVALIS!$B$27 -> 43532.018 | X20: =VIVALIS!$C$27 -> 32203.895 | Y20: =IF(X20=0,0,W20/X20-1) -> 0.35176251 | AA20: =VIVALIS!$B$18 -> 0 | AB20: =VIVALIS!$C$18 -> 0 | AC20: =IF(AB20=0,0,AA20/AB20-1) -> 0 | AE20: =VIVALIS!$B$28 -> 0 | AF20: =VIVALIS!$C$28 -> 0 | AG20: =IF(AF20=0,0,AE20/AF20-1) -> 0 | AI20: =AE20+AA20+K20+G20+C20+O20+S20+W20 -> 993723.27 | AJ20: =AF20+AB20+L20+H20+D20+P20+T20+X20 -> 1359043.2 | AK20: =IF(AJ20=0,0,AI20/AJ20-1) -> -0.26880673 | AL20: =C20+G20-'Syn prin concurents'!E20 -> 0 | AM20: =D20+H20-'Syn prin concurents'!F20 -> 0.001 | AN20: =K20+O20+S20+W20-'Syn prin concurents'!I20 -> 0 | AO20: =L20+P20+T20+X20-'Syn prin concurents'!J20 -> 0 | AP20: =AA20-'Syn prin concurents'!M20 -> 0 | AQ20: =AB20-'Syn prin concurents'!N20 -> 0 | AR20: =AE20-'Syn prin concurents'!Q20 -> 0 | AS20: =AF20-'Syn prin concurents'!R20 -> 0 | AT20: =AI20-'Syn prin concurents'!U20 -> 0 | AU20: =AJ20-'Syn prin concurents'!V20 -> 0.0010000002
A21: Part de marché | C21: =C20/C$30 -> 0.10056065 | D21: =D20/D$30 -> 0.17337106 | E21: =(C21-D21)*100 -> -7.2810409 | G21: =G20/G$30 -> 0.12372437 | H21: =H20/H$30 -> 0.14853335 | I21: =(G21-H21)*100 -> -2.4808977 | K21: =K20/K$30 -> 0.19263512 | L21: =L20/L$30 -> 0.22186762 | M21: =(K21-L21)*100 -> -2.9232495 | O21: =O20/O$30 -> 0.10175918 | P21: =P20/P$30 -> 0.14398093 | Q21: =(O21-P21)*100 -> -4.2221741 | S21: =S20/S$30 -> 0.11094011 | T21: =T20/T$30 -> 0.11385811 | U21: =(S21-T21)*100 -> -0.29179937 | W21: =W20/W$30 -> 0.054432259 | X21: =X20/X$30 -> 0.049865304 | Y21: =(W21-X21)*100 -> 0.45669546 | AA21: =AA20/AA$30 -> 0 | AB21: =AB20/AB$30 -> 0 | AC21: =(AA21-AB21)*100 -> 0 | AE21: =AE20/AE$30 -> 0 | AF21: =AF20/AF$30 -> 0 | AG21: =(AE21-AF21)*100 -> 0 | AI21: =AI20/AI$30 -> 0.11022357 | AJ21: =AJ20/AJ$30 -> 0.15655506 | AK21: =(AI21-AJ21)*100 -> -4.6331488 | AL21: =C21+G21-'Syn prin concurents'!E21 -> 0.1120449 | AM21: =D21+H21-'Syn prin concurents'!F21 -> 0.16125559 | AN21: =K21+O21+S21+W21-'Syn prin concurents'!I21 -> 0.34096431 | AO21: =L21+P21+T21+X21-'Syn prin concurents'!J21 -> 0.37280268 | AP21: =AA21-'Syn prin concurents'!M21 -> 0 | AQ21: =AB21-'Syn prin concurents'!N21 -> 0 | AR21: =AE21-'Syn prin concurents'!Q21 -> 0 | AS21: =AF21-'Syn prin concurents'!R21 -> 0 | AT21: =AI21-'Syn prin concurents'!U21 -> 0 | AU21: =AJ21-'Syn prin concurents'!V21 -> 8.802646e-06
